Workbook

Sheet Start
B2: Amazon.de Seller Workbook — v4
B3: Choose the product, plan the order, track the money — one file. Follow the order below for a new product; every sheet links back here.
B5: Legend: BLUE on YELLOW = you type here · BLACK = formula, do not overwrite · GREEN = pulled from another sheet automatically.
B6: Cells with a small red corner marker have an (i) note — hover to read what the number means and what to do with it.
B8: Sheet | C8: What it answers | D8: Open | E8: Where you stand (live)
B9: Guide | C9: How to use the file + where every report lives | D9: =HYPERLINK("#'Guide'!B2","Open →") -> Open → | E9: ="read once before starting" -> read once before starting
B10: 1 Seasonality | C10: Is demand seasonal? When does it ramp? | D10: =HYPERLINK("#'1 Seasonality'!B2","Open →") -> Open → | E10: =IFERROR("amplitude "&TEXT('1 Seasonality'!C29,"0.00")&"x · ramp "&'1 Seasonality'!C34&" · YoY "&TEXT('1 Seasonality'!C31,"+0.0%;-0.0%"),"fill Sheet 1") -> amplitude 005x · ramp Apr · YoY +09%
B11: 2 Order timing | C11: By when must the order be placed? | D11: =HYPERLINK("#'2 Order timing'!B2","Open →") -> Open → | E11: =IFERROR("order by "&TEXT('2 Order timing'!C20,"yyyy-mm-dd")&" · "&TEXT('2 Order timing'!C21,"0")&" days left","fill Sheet 2") -> order by yyyy-00-dd · 38 days left
B12: 3 Unit economics | C12: Do I earn enough per unit before ads? | D12: =HYPERLINK("#'3 Unit economics'!B2","Open →") -> Open → | E12: =IFERROR("margin "&TEXT('3 Unit economics'!C30,"0.0%")&" · breakeven ACOS "&TEXT('3 Unit economics'!C31,"0.0%"),"fill Sheet 3") -> margin 40% · breakeven ACOS 34%
B13: 4 Selection | C13: Does the product pass every gate? | D13: =HYPERLINK("#'4 Selection'!B2","Open →") -> Open → | E13: =IFERROR("A: "&'4 Selection'!C32&" · B "&'4 Selection'!C33&" · C "&'4 Selection'!C34,"fill Sheet 4") -> A: CLEAN · B 8 / 8 · C 5 / 5
B14: 5 Niche scorecard | C14: Which candidate deserves my research time? | D14: =HYPERLINK("#'5 Niche scorecard'!B2","Open →") -> Open → | E14: =IF(COUNT('5 Niche scorecard'!D32:K32)=0,"no niches scored yet","best score "&TEXT(MAX('5 Niche scorecard'!D32:K32),"0")&"/100") -> best score 65/100
B15: 6 Order size | C15: How many units in the first order? | D15: =HYPERLINK("#'6 Order size'!B2","Open →") -> Open → | E15: =IFERROR("order "&TEXT('6 Order size'!C24,"#,##0")&" units","fill Sheets 3 + 6") -> order 386,0 units
B16: 7 PPC planner | C16: What can I pay for ads? Where is waste? | D16: =HYPERLINK("#'7 PPC planner'!B2","Open →") -> Open → | E16: =IFERROR("target ACOS "&TEXT('7 PPC planner'!C11,"0.0%")&" · wasted "&TEXT('7 PPC planner'!C25,"#,##0")&" € found","fill Sheet 7") -> target ACOS 10% · wasted 45,0 € found
B17: 8 Cash flow | C17: Do I stay above zero the whole year? | D17: =HYPERLINK("#'8 Cash flow'!B2","Open →") -> Open → | E17: =IFERROR("lowest cash point "&TEXT('8 Cash flow'!C32,"#,##0")&" €","fill Sheet 8") -> lowest cash point 1509,0 €
B18: 9 Monthly P&L | C18: Am I actually making money each month? | D18: =HYPERLINK("#'9 Monthly P&L'!B2","Open →") -> Open → | E18: =IF('9 Monthly P&L'!K18=0,"no months filled yet","YTD profit "&TEXT('9 Monthly P&L'!K18,"#,##0")&" €") -> YTD profit 1178,0 €
B19: 10 Money recovery | C19: Does Amazon owe me money? | D19: =HYPERLINK("#'10 Money recovery'!B2","Open →") -> Open → | E19: ="unclaimed flags: "&'10 Money recovery'!C5 -> unclaimed flags: 1
B20: 11 Review themes | C20: Which complaint do I attack? Is the wall fake? | D20: =HYPERLINK("#'11 Review themes'!B2","Open →") -> Open → | E20: =IF('11 Review themes'!C19="—","no themes entered yet",'11 Review themes'!C19&" ("&TEXT('11 Review themes'!C20,"0%")&")") -> Wobbles / mount comes loose (43%)
B21: 12 Multi-year plan | C21: Do 3 years of staggered launches stay funded? | D21: =HYPERLINK("#'12 Multi-year plan'!B2","Open →") -> Open → | E21: =IFERROR("lowest cash across 12 quarters "&TEXT('12 Multi-year plan'!C32,"#,##0")&" €","fill Sheet 12") -> lowest cash across 12 quarters -3406,0 €
B23: New product path: 1 → 2 → 3 → 4 (run 5 to compare several niches) → 6 → 7 → 8, then order.
B24: Already selling: 9 → 10 → 11 once a month, 7 every two weeks. Planning the business, not one product: 12.
B26: v4 · 2026-08-25 · Built for a non-EU (deemed supplier) seller on Amazon.de. Educational tool, not tax or legal advice.

Sheet Guide
B1: =HYPERLINK("#Start!B2","← Start") -> ← Start
B2: Guide: how to use this workbook
B4: The rules
B5: Blue text on yellow fill = you type here. Black = formula, never overwrite. Green = pulled from another sheet. Hover cells with a red corner marker for (i) explanations. Work sheets 1→8 in order for a new product; sheets 9–11 are your monthly routine after launch.
B7: Measure seasonality BEFORE profit math — it is faster and kills more candidates. Never measure seasonality on a listing younger than 18 months: a young listing's chart is launch curve + season, inseparable. Measure the CATEGORY on data that existed before the listing did.
B9: Where the research data comes from (sheets 1–5)
B10: Search history: Helium 10 Cerebro/Magnet → chart icon next to search volume → export. Amazon's own data: Product Opportunity Explorer in Seller Central (free). Old competitors' sales: Helium 10 Trendster, 3–5 ASINs older than 2 years. Same-month-last-year: Xray columns 'Last Year Sales' / 'Sales YoY'. Shape check: Google Trends, region Germany, 5-year window (relative values only — shape, never volume).
B13: BSR is a rank, weighted to recent sales: if a whole category halves in December, ranks barely move, so BSR UNDERSTATES seasonal amplitude. Use units or search volume for amplitude; BSR only to compare products at one moment.
B15: Where the operating reports live (sheets 7, 9, 10)
B16: Search Term Report (Sheet 7): Advertising console → Sponsored Products → Reports → Search term. Choose 30–60 days.
B17: Date Range / transaction totals (Sheet 9): Seller Central → Payments → Reports repository → Date Range Report (Summary).
B18: Inventory Adjustments (Sheet 10): Reports → Fulfilment by Amazon → Inventory → Inventory Adjustments. Filter reasons: Lost, Damaged, Disposed.
B19: Reimbursements (Sheet 10): Reports → Fulfilment by Amazon → Payments → Reimbursements.
... B33: This file is an educational tool, not tax, legal or investment advice. Amazon fees change every December/January — cross-check your category's rates in Seller Central before big decisions.

Sheet 1 Seasonality
B1: =HYPERLINK("#Start!B2","← Start") -> ← Start
B2: Seasonality index from monthly demand
B3: Enter 24 months of search volume for the niche keyword. The sheet computes the shape of the year and a verdict.
B4: Keyword / niche | C4: fahrradhelm | G4: Example shown. Replace with your own export.
B5: Marketplace | C5: Amazon.de
B6: Data source | C6: H10 Cerebro Search Volume History
B7: Export date | C7: 46248
B9: Month | C9: Volume yr 1 | D9: Volume yr 2 | E9: Avg volume | F9: Index | G9: YoY % | H9: Notes | I9: Flag
B10: Jan | C10: 9800 | D10: 10400 | E10: =IF(COUNT(C10:D10)=0,"",AVERAGE(C10:D10)) -> 10100 | F10: =IF($E10="","",$E10/AVERAGE($E$10:$E$21)) -> 0.42879887 | G10: =IF(COUNT(C10:D10)<2,"",D10/C10-1) -> 0.06122449 | I10: =IF(OR($F10="",$F$21=""),0,IF(AND($F10>=1,$F$21<1),1,0)) -> 0
B11: Feb | C11: 11500 | D11: 12600 | E11: =IF(COUNT(C11:D11)=0,"",AVERAGE(C11:D11)) -> 12050 | F11: =IF($E11="","",$E11/AVERAGE($E$10:$E$21)) -> 0.51158677 | G11: =IF(COUNT(C11:D11)<2,"",D11/C11-1) -> 0.095652174 | I11: =IF(OR($F11="",$F$10=""),0,IF(AND($F11>=1,$F$10<1),1,0)) -> 0
B12: Mar | C12: 21000 | D12: 23500 | E12: =IF(COUNT(C12:D12)=0,"",AVERAGE(C12:D12)) -> 22250 | F12: =IF($E12="","",$E12/AVERAGE($E$10:$E$21)) -> 0.94463117 | G12: =IF(COUNT(C12:D12)<2,"",D12/C12-1) -> 0.11904762 | I12: =IF(OR($F12="",$F$11=""),0,IF(AND($F12>=1,$F$11<1),1,0)) -> 0
B13: Apr | C13: 29000 | D13: 31500 | E13: =IF(COUNT(C13:D13)=0,"",AVERAGE(C13:D13)) -> 30250 | F13: =IF($E13="","",$E13/AVERAGE($E$10:$E$21)) -> 1.2842738 | G13: =IF(COUNT(C13:D13)<2,"",D13/C13-1) -> 0.086206897 | I13: =IF(OR($F13="",$F$12=""),0,IF(AND($F13>=1,$F$12<1),1,0)) -> 1
B14: May | C14: 34000 | D14: 37000 | E14: =IF(COUNT(C14:D14)=0,"",AVERAGE(C14:D14)) -> 35500 | F14: =IF($E14="","",$E14/AVERAGE($E$10:$E$21)) -> 1.5071643 | G14: =IF(COUNT(C14:D14)<2,"",D14/C14-1) -> 0.088235294 | I14: =IF(OR($F14="",$F$13=""),0,IF(AND($F14>=1,$F$13<1),1,0)) -> 0
B15: Jun | C15: 38000 | D15: 41000 | E15: =IF(COUNT(C15:D15)=0,"",AVERAGE(C15:D15)) -> 39500 | F15: =IF($E15="","",$E15/AVERAGE($E$10:$E$21)) -> 1.6769857 | G15: =IF(COUNT(C15:D15)<2,"",D15/C15-1) -> 0.078947368 | I15: =IF(OR($F15="",$F$14=""),0,IF(AND($F15>=1,$F$14<1),1,0)) -> 0
B16: Jul | C16: 41000 | D16: 45000 | E16: =IF(COUNT(C16:D16)=0,"",AVERAGE(C16:D16)) -> 43000 | F16: =IF($E16="","",$E16/AVERAGE($E$10:$E$21)) -> 1.8255793 | G16: =IF(COUNT(C16:D16)<2,"",D16/C16-1) -> 0.097560976 | I16: =IF(OR($F16="",$F$15=""),0,IF(AND($F16>=1,$F$15<1),1,0)) -> 0
B17: Aug | C17: 33000 | D17: 36000 | E17: =IF(COUNT(C17:D17)=0,"",AVERAGE(C17:D17)) -> 34500 | F17: =IF($E17="","",$E17/AVERAGE($E$10:$E$21)) -> 1.464709 | G17: =IF(COUNT(C17:D17)<2,"",D17/C17-1) -> 0.090909091 | I17: =IF(OR($F17="",$F$16=""),0,IF(AND($F17>=1,$F$16<1),1,0)) -> 0
B18: Sep | C18: 22000 | D18: 24000 | E18: =IF(COUNT(C18:D18)=0,"",AVERAGE(C18:D18)) -> 23000 | F18: =IF($E18="","",$E18/AVERAGE($E$10:$E$21)) -> 0.97647267 | G18: =IF(COUNT(C18:D18)<2,"",D18/C18-1) -> 0.090909091 | I18: =IF(OR($F18="",$F$17=""),0,IF(AND($F18>=1,$F$17<1),1,0)) -> 0
B19: Oct | C19: 14000 | D19: 15200 | E19: =IF(COUNT(C19:D19)=0,"",AVERAGE(C19:D19)) -> 14600 | F19: =IF($E19="","",$E19/AVERAGE($E$10:$E$21)) -> 0.61984787 | G19: =IF(COUNT(C19:D19)<2,"",D19/C19-1) -> 0.085714286 | I19: =IF(OR($F19="",$F$18=""),0,IF(AND($F19>=1,$F$18<1),1,0)) -> 0
B20: Nov | C20: 9200 | D20: 9900 | E20: =IF(COUNT(C20:D20)=0,"",AVERAGE(C20:D20)) -> 9550 | F20: =IF($E20="","",$E20/AVERAGE($E$10:$E$21)) -> 0.40544843 | G20: =IF(COUNT(C20:D20)<2,"",D20/C20-1) -> 0.076086957 | I20: =IF(OR($F20="",$F$19=""),0,IF(AND($F20>=1,$F$19<1),1,0)) -> 0
B21: Dec | C21: 8100 | D21: 8600 | E21: =IF(COUNT(C21:D21)=0,"",AVERAGE(C21:D21)) -> 8350 | F21: =IF($E21="","",$E21/AVERAGE($E$10:$E$21)) -> 0.35450203 | G21: =IF(COUNT(C21:D21)<2,"",D21/C21-1) -> 0.061728395 | I21: =IF(OR($F21="",$F$20=""),0,IF(AND($F21>=1,$F$20<1),1,0)) -> 0
B22: Total | C22: =SUM(C10:C21) -> 270600 | D22: =SUM(D10:D21) -> 294700 | E22: =SUM(E10:E21) -> 282650 | G22: =IF(OR(C22=0,D22=0),"",D22/C22-1) -> 0.089061345
B24: Results
B25: Peak month | C25: =IF(COUNT($F$10:$F$21)=0,"",INDEX($B$10:$B$21,MATCH(MAX($F$10:$F$21),$F$10:$F$21,0))) -> Jul
B26: Lowest month | C26: =IF(COUNT($F$10:$F$21)=0,"",INDEX($B$10:$B$21,MATCH(MIN($F$10:$F$21),$F$10:$F$21,0))) -> Dec
B27: Peak index | C27: =IF(COUNT($F$10:$F$21)=0,"",MAX($F$10:$F$21)) -> 1.8255793
B28: Lowest index | C28: =IF(COUNT($F$10:$F$21)=0,"",MIN($F$10:$F$21)) -> 0.35450203
B29: Amplitude (peak / lowest non-zero) | C29: =IFERROR(MAX($F$10:$F$21)/_xlfn.MINIFS($F$10:$F$21,$F$10:$F$21,">0"),"") -> 5.1497006
B30: Top-4 months' share of the year | C30: =IFERROR((LARGE($E$10:$E$21,1)+LARGE($E$10:$E$21,2)+LARGE($E$10:$E$21,3)+LARGE($E$10:$E$21,4))/SUM($E$10:$E$21),"") -> 0.53953653
B31: Category growth year over year | C31: =IF(OR(C22=0,D22=0),"",D22/C22-1) -> 0.089061345
B32: Months with data (needs 12) | C32: =COUNT($E$10:$E$21) -> 12
B33: Verdict | C33: =IF(C32<12,"Fill all 12 months before trusting the verdict.",IF(COUNTIF($E$10:$E$21,0)>0,"A zero-demand month: extreme single-season. Avoid as a first product.",IF(C29<1.5,"Flat demand. Order timing is not critical.",IF(C29<2.5,"Moderate seasonality. Time the order, but sales run all year.",IF(C29<4,"Strong seasonality. Stock must land 4 weeks before the ramp; exit the peak with low inventory.","Single-season product. A working-capital trap for a first product."))))) -> Single-season product. A working-capital trap for a first product.
B34: Ramp month (index crosses 1.00 upward) | C34: =IFERROR(INDEX($B$10:$B$21,MATCH(1,$I$10:$I$21,0)),"—") -> Apr
B35: Demand direction (from YoY) | C35: =IF(C31="","Fill both years first.",IF(C31>0.05,"GROWING (>+5%). Tailwind. Check it is not one viral ASIN: in Xray, is page-1 revenue spread across many listings?",IF(C31>=-0.05,"FLAT (-5%..+5%). Fine for entry - you win by taking share, not riding the tide.",IF(C31>=-0.15,"COOLING (-5%..-15%). Google Trends, DE, 5 years: post-boom plateau = acceptable; steady multi-year slide = drop.","DECLINING (<-15%). Fails the demand test - drop unless Trends shows a clearly temporary dip.")))) -> GROWING (>+5%). Tailwind. Check it is not one viral ASIN: in Xray, is page-1 revenue spread across many listings?
B36: Amplitude = shape of the year; YoY = does the category grow. They answer different questions.
B37: Top-4 share above 60% = a four-month business carrying twelve months of costs.
B38: YoY verdict bands: >+5% growing · -5..+5 flat · -5..-15 cooling (verify on Trends) · below -15% declining.

Sheet 2 Order timing
B1: =HYPERLINK("#Start!B2","← Start") -> ← Start
B2: Back-calculating the order date from the ramp month
B3: Target on-stock date = 4 weeks before the ramp month from Sheet 1.
B5: Ramp month (from Sheet 1) | C5: ='1 Seasonality'!C34 -> Apr
B6: Suggested on-stock date (1st of ramp month − 28 days) | C6: =IFERROR(DATE(YEAR(TODAY())+IF(DATE(YEAR(TODAY()),MATCH($C$5,'1 Seasonality'!$B$10:$B$21,0),1)-28<=TODAY(),1,0),MATCH($C$5,'1 Seasonality'!$B$10:$B$21,0),1)-28,"fill Sheet 1 first") -> 46450
B7: Target on-stock date (your choice) | C7: 46450 | E7: Defaults to the suggested date. Land earlier if peak-season check-in delays are likely.
B9: Supply-cycle stage | C9: Days
B10: Certification / test protocols (0 if unregulated) | C10: 0 | E10: PPE, electrical, toys: add 60–120 days.
B11: Supplier selection and samples | C11: 21 | E11: Two sample rounds is normal.
B12: Production | C12: 40 | E12: 30–45 days for a 300–1,000-unit batch.
B13: Factory holiday buffer (CNY, Golden Week) | C13: 0 | E13: Chinese New Year (late Jan–Feb): add 20–30 days. Golden Week (early Oct): add ~7.
B14: Sea freight to Germany | C14: 40 | E14: 35–45 days port-to-port plus the inland leg.
B15: Customs clearance | C15: 5 | E15: 3–7 days. Non-EU importer: you need an EORI and normally an indirect customs representative (usually the forwarder). Agree incoterms before production starts.
B16: FBA inbound and check-in | C16: 10 | E16: 7–14 days, longer in Q4.
B17: Safety buffer | C17: 15 | E17: Never set this to zero.
B18: Total lead time (days) | C18: =SUM(C10:C17) -> 131
B20: Order must be placed by | C20: =C7-C18 -> 46319
B21: Days from today | C21: =C7-C18-TODAY() -> 38
B23: Negative = the season is already lost. Plan next year or change the product.

Sheet 3 Unit economics
B1: =HYPERLINK("#Start!B2","← Start") -> ← Start
B2: Contribution margin per unit, Amazon.de
B3: Non-EU seller: Amazon acts as deemed supplier, so the 19% German VAT never reaches you. Net revenue = gross / 1.19.
B5: Inputs
B6: Sale price, gross incl. VAT (EUR) | C6: 59.99 | E6: What the buyer pays.
B7: VAT rate | C7: 0.19 | E7: German standard rate.
B8: Referral fee rate | C8: 0.15 | E8: Check your category — Dec 2025/Jan 2026 updates cut several sub-€20 categories.
B9: Referral charged on gross price? 1=yes 0=no | C9: 1 | E9: Amazon EU charges referral fees on the VAT-inclusive total sales price — leave at 1.
B10: FBA fulfilment fee (EUR) | C10: 4.55 | E10: From the listing or the Revenue Calculator.
B11: Storage per unit sold (EUR) | C11: 0.62 | E11: Litres × monthly rate × months of cover. Oct–Dec rates are ~2–3× higher.
B12: Returns rate | C12: 0.07 | E12: Size/fit products run 8–12%.
B13: Return cost, share of net price | C13: 0.7 | E13: Lost fees + processing + unsellable stock.
B14: EXW unit cost (EUR) | C14: 10 | E14: Supplier price.
B15: Freight per unit (EUR) | C15: 2.2 | E15: Rate per m³ × unit volume.
B16: Import duty rate (on CIF value) | C16: 0.027 | E16: Check the TARIC code. Duty base = goods + freight, not EXW alone.
B17: Prep, labels, inspection per unit (EUR) | C17: 0.4 | E17: Incl. GPSR & EPR marking.
B18: Turnover tax rate (home country) | C18: 0.01 | E18: Georgian small-business IE: 1% of turnover. Confirm the base with your accountant.
B20: Calculation
B21: Net revenue (ex VAT) | C21: =C6/(1+C7) -> 50.411765
B22: Referral fee | C22: =-IF(C9=1,C6*C8,C21*C8) -> -8.9985
B23: FBA fulfilment fee | C23: =-C10 -> -4.55
B24: Storage | C24: =-C11 -> -0.62
B25: Cost of returns | C25: =-C12*C13*C21 -> -2.4701765
B26: Net after Amazon (payout per unit) | C26: =SUM(C21:C25) -> 33.773088 | E26: What Amazon disburses per unit sold, before your own costs.
B27: Landed cost per unit | C27: =-(C14+C15+(C14+C15)*C16+C17) -> -12.9294 | E27: Duty on CIF base: (EXW + freight) × duty rate.
B28: Turnover tax (on net revenue) | C28: =-C18*C21 -> -0.50411765
B29: Contribution margin per unit | C29: =C26+C27+C28 -> 20.339571
B30: Margin on net revenue | C30: =IFERROR(C29/C21,"") -> 0.40346873 | E30: Target: 35%+ before advertising.
B31: Breakeven ACOS (ad console basis) | C31: =IFERROR(C29/C6,"") -> 0.33904935 | E31: The console measures sales incl. VAT → divide by the GROSS price.
B32: Max landed cost at 35% margin | C32: =C26+C28-0.35*C21 -> 15.624853
B33: Max EXW price to quote supplier | C33: =(C32-C17-C15*(1+C16))/(1+C16) -> 12.624589 | E33: Hand THIS number to the supplier as your ceiling.
B34: Profit tax reserve (info — taxes yearly PROFIT, not the unit; not a gate) | C34: 0.3 | E34: Year-end tax on profit (German income tax + trade tax if the business is German-managed; Georgian 1%-regime if the Georgian model holds - ask a Steuerberater). Reserve this share of every euro of contribution; it is not a per-unit cost and does not move the 35/30 bands.
B35: Contribution after tax reserve | C35: =C29*(1-C34) -> 14.237699
B36: Price needed for 35% margin (green) | C36: =IFERROR((C10+C11-C27)/((1-C12*C13-C18-0.35)/(1+C7)-IF(C9=1,C8,C8/(1+C7))),"") -> 52.214027 | E36: The inverse of the margin question: at the costs typed above, this gross price reaches 35%. If the market price on page 1 is below this number, the costs are wrong for the niche - not the price.
B37: Price needed for 30% margin (yellow) | C37: =IFERROR((C10+C11-C27)/((1-C12*C13-C18-0.3)/(1+C7)-IF(C9=1,C8,C8/(1+C7))),"") -> 46.569267
B38: Max EXW at 30% (yellow ceiling) | C38: =((C26+C28-0.3*C21)-C17-C15*(1+C16))/(1+C16) -> 15.078911
B40: Import VAT (19%) is paid at customs on customs value + duty and is recoverable via your German VAT registration — a cash-flow item (see Sheet 8), not a unit cost.
B41: Cross-check the FBA fee against real dimensions: €4.55 is not a 12 cm box. H10 exports sometimes mislabel inches as cm.
B43: Order totals — quick math (the real order plan lives in Sheets 6 + 8)
B44: Sets in this order | C44: 300
...

Sheet 4 Selection
B1: =HYPERLINK("#Start!B2","← Start") -> ← Start
B2: Selection checklist. Any NO in block A is an automatic reject.
B4: A. Compliance & IP exclusions — YES only if this does NOT apply. | C4: Passed?
B5: Not worn for body protection (EU PPE Regulation 2016/425) | C5: YES | E5: Helmets, harnesses, goggles, gloves, hi-vis. Cat II needs a notified body.
B6: No battery, plug, motor or LED | C6: YES | E6: Triggers LVD, EMC, RoHS, WEEE, BattG.
B7: Not intended for children under 14 | C7: YES | E7: Toy Safety Directive 2009/48/EC.
B8: No contact with food, drink or skin | C8: YES | E8: LFGB, cosmetics regulation, migration tests.
B9: No medical, health or veterinary claims | C9: YES | E9: MDR, health-claims rules.
B10: Nothing load-bearing, nothing that arrests a fall | C10: YES | E10: The PPE trap under another name.
B11: No blocking IP: designs, patents, trademarks checked | C11: YES | E11: EUIPO eSearch, DPMA register, Google Patents. Design infringement is the #1 private-label account killer in DE.
B12: EU Responsible Person appointed (GPSR) | C12: YES | E12: Mandatory for a non-EU seller on any consumer product.
B13: Packaging EPR done: LUCID + PPWR authorised representative | C13: YES | E13: LUCID mandatory since 2022; PPWR AR duty applies since 12 Aug 2026.
B15: B. Demand and competition | C15: Passed?
B16: Page-1 revenue of €40,000+/month | C16: YES | E16: Xray: sum of top-10 organic results.
B17: Top ASIN holds under 40% of page revenue | C17: YES | E17: Higher = one brand plus noise.
B18: At least 2 page-1 listings launched in last 12 months | C18: YES | E18: Proves entry still works.
B19: Zero to two page-1 ASINs above 500 reviews | C19: YES | E19: Count REAL reviews — run Sheet 11's fake check first.
B20: No Amazon Basics / Amazon Retail on page 1 | C20: YES
B21: China + Hong Kong sellers under 60% of page 1 | C21: YES
B22: A dominant negative-review theme of at least 40% | C22: YES | E22: From Sheet 11.
B23: Weakest page-1 ASINs rated 4.3 or below | C23: YES | E23: A 4.7 field gives no point of attack.
B25: C. Seasonality and cash | C25: Passed?
B26: Amplitude below 2.5x, OR the order lands before the ramp | C26: YES | E26: Sheets 1 + 2.
B27: Top-4 months hold under 60% of the year | C27: YES
B28: The order-by date is still in the future | C28: YES | E28: Sheet 2.
B29: Contribution margin 35%+ before advertising | C29: YES | E29: Sheet 3.
B30: Order + compliance + launch ads fit budget incl. reorder reserve | C30: YES | E30: Sheets 6 + 7 + 8.
B32: Block A result | C32: =IF(COUNTIF(C5:C13,"YES")=9,"CLEAN","REJECT") -> CLEAN
B33: Block B score | C33: =COUNTIF(C16:C23,"YES")&" / 8" -> 8 / 8
B34: Block C score | C34: =COUNTIF(C26:C30,"YES")&" / 5" -> 5 / 5
B36: Go ahead only if A = CLEAN, B ≥ 7/8, C = 5/5.
B38: Review wall — how long until you catch up? (v4)
B39: Median review count of page-1 top ASINs | C39: 75 | E39: Xray: sort page 1 by rank, take the median review count of the top 10 — not the average (one 5,000-review giant distorts it).
B40: Your expected units sold per month | C40: 300
B41: Review rate (reviews per unit sold) | C41: 0.015 | E41: Organic review rate on Amazon.de runs 1–2% of units; Vine (30 units) adds a one-off ~25 at the start.
B42: Reviews you gain per month | C42: =IFERROR(C40*C41,"") -> 4.5
B43: Months to reach the page-1 median | C43: =IFERROR(C39/C42,"") -> 16.666667
B44: =IF(C43="","",IF(C43<=6,"OK — the wall is reachable within ~6 months.",IF(C43<=12,"CAUTION — about a year of grinding at a review deficit; budget PPC above target ACOS for that long.","FLAG — over a year behind on social proof. You need Vine + a real differentiation angle (Sheet 11), or a lower-wall niche."))) -> FLAG — over a year behind on social proof. You need Vine + a real differentiation angle (Sheet 11), or a lower-wall niche.
B46: Textiles & plant materials (v4): anything textile sold in DE needs fibre-composition labelling per EU Textile Regulation 1007/2011 (TextilKennzVO enforcement) — 'Polyester' is a defined term, marketing names are illegal on the label. Buckwheat / spelt / other plant fillings (e.g. japanisches kissen) additionally risk phytosanitary import rules + food-contact-adjacent scrutiny: confirm the filling's import status BEFORE sampling. Add both to Block A row 8/13 thinking.

Sheet 5 Niche scorecard
B1: =HYPERLINK("#Start!B2","← Start") -> ← Start
B2: Niche comparison scorecard — up to 8 candidates
B3: Fill the yellow inputs from Xray/Cerebro and from Sheets 1–3 run per niche. Any hard gate failure disqualifies regardless of score.
B4: Budget incl. reorder reserve (EUR) | C4: 6500
B5: Inputs | C5: Source | D5: Niche 1 | E5: Niche 2 | F5: Niche 3 | G5: Niche 4 | H5: Niche 5 | I5: Niche 6 | J5: Niche 7 | K5: Niche 8
B6: Niche / keyword | C6: — | D6: fahrradhelm
B7: Avg monthly search volume (context, not scored) | C7: Cerebro | D7: 23500
B8: Page-1 revenue, €/month | C8: Xray | D8: 95000
B9: Top ASIN share of page-1 revenue | C9: Xray | D9: 0.28
B10: Page-1 ASINs with >500 REAL reviews (count) | C10: Xray + Sheet 11 | D10: 5
B11: Page-1 listings launched in last 12 months | C11: Xray | D11: 2
B12: Weak competitor rated ≤4.3 exists? (1/0) | C12: Xray | D12: 1
B13: China + HK share of page 1 | C13: Xray | D13: 0.55
B14: Seasonality amplitude | C14: Sheet 1 | D14: 5.15
B15: Top-4 months' share of year | C15: Sheet 1 | D15: 0.54
B16: Contribution margin, % of net | C16: Sheet 3 | D16: 0.4
B17: First order + compliance cash need, € | C17: Sheets 6+8 | D17: 9000
B18: Compliance block A passed? (YES/NO) | C18: Sheet 4 | D18: NO
B20: Scores (auto, 0–2 each) | C20: Weight
B21: Demand: page-1 revenue | C21: 0.15 | D21: =IF(D8="","",IF(D8>=40000,2,IF(D8>=20000,1,0))) -> 2 | E21: =IF(E8="","",IF(E8>=40000,2,IF(E8>=20000,1,0))) | F21: =IF(F8="","",IF(F8>=40000,2,IF(F8>=20000,1,0))) | G21: =IF(G8="","",IF(G8>=40000,2,IF(G8>=20000,1,0))) | H21: =IF(H8="","",IF(H8>=40000,2,IF(H8>=20000,1,0))) | I21: =IF(I8="","",IF(I8>=40000,2,IF(I8>=20000,1,0))) | J21: =IF(J8="","",IF(J8>=40000,2,IF(J8>=20000,1,0))) | K21: =IF(K8="","",IF(K8>=40000,2,IF(K8>=20000,1,0)))
B22: Fragmentation: top-ASIN share | C22: 0.1 | D22: =IF(D9="","",IF(D9<0.3,2,IF(D9<=0.4,1,0))) -> 2 | E22: =IF(E9="","",IF(E9<0.3,2,IF(E9<=0.4,1,0))) | F22: =IF(F9="","",IF(F9<0.3,2,IF(F9<=0.4,1,0))) | G22: =IF(G9="","",IF(G9<0.3,2,IF(G9<=0.4,1,0))) | H22: =IF(H9="","",IF(H9<0.3,2,IF(H9<=0.4,1,0))) | I22: =IF(I9="","",IF(I9<0.3,2,IF(I9<=0.4,1,0))) | J22: =IF(J9="","",IF(J9<0.3,2,IF(J9<=0.4,1,0))) | K22: =IF(K9="","",IF(K9<0.3,2,IF(K9<=0.4,1,0)))
B23: Review moat | C23: 0.1 | D23: =IF(D10="","",IF(D10<=2,2,IF(D10<=4,1,0))) -> 0 | E23: =IF(E10="","",IF(E10<=2,2,IF(E10<=4,1,0))) | F23: =IF(F10="","",IF(F10<=2,2,IF(F10<=4,1,0))) | G23: =IF(G10="","",IF(G10<=2,2,IF(G10<=4,1,0))) | H23: =IF(H10="","",IF(H10<=2,2,IF(H10<=4,1,0))) | I23: =IF(I10="","",IF(I10<=2,2,IF(I10<=4,1,0))) | J23: =IF(J10="","",IF(J10<=2,2,IF(J10<=4,1,0))) | K23: =IF(K10="","",IF(K10<=2,2,IF(K10<=4,1,0)))
B24: Fresh entrants | C24: 0.1 | D24: =IF(D11="","",IF(D11>=2,2,IF(D11>=1,1,0))) -> 2 | E24: =IF(E11="","",IF(E11>=2,2,IF(E11>=1,1,0))) | F24: =IF(F11="","",IF(F11>=2,2,IF(F11>=1,1,0))) | G24: =IF(G11="","",IF(G11>=2,2,IF(G11>=1,1,0))) | H24: =IF(H11="","",IF(H11>=2,2,IF(H11>=1,1,0))) | I24: =IF(I11="","",IF(I11>=2,2,IF(I11>=1,1,0))) | J24: =IF(J11="","",IF(J11>=2,2,IF(J11>=1,1,0))) | K24: =IF(K11="","",IF(K11>=2,2,IF(K11>=1,1,0)))
B25: Weak competitor to attack | C25: 0.1 | D25: =IF(D12="","",IF(D12=1,2,0)) -> 2 | E25: =IF(E12="","",IF(E12=1,2,0)) | F25: =IF(F12="","",IF(F12=1,2,0)) | G25: =IF(G12="","",IF(G12=1,2,0)) | H25: =IF(H12="","",IF(H12=1,2,0)) | I25: =IF(I12="","",IF(I12=1,2,0)) | J25: =IF(J12="","",IF(J12=1,2,0)) | K25: =IF(K12="","",IF(K12=1,2,0))
B26: CN/HK saturation | C26: 0.05 | D26: =IF(D13="","",IF(D13<0.4,2,IF(D13<0.6,1,0))) -> 1 | E26: =IF(E13="","",IF(E13<0.4,2,IF(E13<0.6,1,0))) | F26: =IF(F13="","",IF(F13<0.4,2,IF(F13<0.6,1,0))) | G26: =IF(G13="","",IF(G13<0.4,2,IF(G13<0.6,1,0))) | H26: =IF(H13="","",IF(H13<0.4,2,IF(H13<0.6,1,0))) | I26: =IF(I13="","",IF(I13<0.4,2,IF(I13<0.6,1,0))) | J26: =IF(J13="","",IF(J13<0.4,2,IF(J13<0.6,1,0))) | K26: =IF(K13="","",IF(K13<0.4,2,IF(K13<0.6,1,0)))
B27: Seasonality amplitude | C27: 0.15 | D27: =IF(D14="","",IF(D14<1.5,2,IF(D14<2.5,1,0))) -> 0 | E27: =IF(E14="","",IF(E14<1.5,2,IF(E14<2.5,1,0))) | F27: =IF(F14="","",IF(F14<1.5,2,IF(F14<2.5,1,0))) | G27: =IF(G14="","",IF(G14<1.5,2,IF(G14<2.5,1,0))) | H27: =IF(H14="","",IF(H14<1.5,2,IF(H14<2.5,1,0))) | I27: =IF(I14="","",IF(I14<1.5,2,IF(I14<2.5,1,0))) | J27: =IF(J14="","",IF(J14<1.5,2,IF(J14<2.5,1,0))) | K27: =IF(K14="","",IF(K14<1.5,2,IF(K14<2.5,1,0)))
B28: Top-4 concentration | C28: 0.05 | D28: =IF(D15="","",IF(D15<0.45,2,IF(D15<0.6,1,0))) -> 1 | E28: =IF(E15="","",IF(E15<0.45,2,IF(E15<0.6,1,0))) | F28: =IF(F15="","",IF(F15<0.45,2,IF(F15<0.6,1,0))) | G28: =IF(G15="","",IF(G15<0.45,2,IF(G15<0.6,1,0))) | H28: =IF(H15="","",IF(H15<0.45,2,IF(H15<0.6,1,0))) | I28: =IF(I15="","",IF(I15<0.45,2,IF(I15<0.6,1,0))) | J28: =IF(J15="","",IF(J15<0.45,2,IF(J15<0.6,1,0))) | K28: =IF(K15="","",IF(K15<0.45,2,IF(K15<0.6,1,0)))
B29: Margin | C29: 0.15 | D29: =IF(D16="","",IF(D16>=0.35,2,IF(D16>=0.3,1,0))) -> 2 | E29: =IF(E16="","",IF(E16>=0.35,2,IF(E16>=0.3,1,0))) | F29: =IF(F16="","",IF(F16>=0.35,2,IF(F16>=0.3,1,0))) | G29: =IF(G16="","",IF(G16>=0.35,2,IF(G16>=0.3,1,0))) | H29: =IF(H16="","",IF(H16>=0.35,2,IF(H16>=0.3,1,0))) | I29: =IF(I16="","",IF(I16>=0.35,2,IF(I16>=0.3,1,0))) | J29: =IF(J16="","",IF(J16>=0.35,2,IF(J16>=0.3,1,0))) | K29: =IF(K16="","",IF(K16>=0.35,2,IF(K16>=0.3,1,0)))
B30: Cash fit vs budget | C30: 0.05 | D30: =IF(D17="","",IF(D17<=0.8*$C$4,2,IF(D17<=$C$4,1,0))) -> 0 | E30: =IF(E17="","",IF(E17<=0.8*$C$4,2,IF(E17<=$C$4,1,0))) | F30: =IF(F17="","",IF(F17<=0.8*$C$4,2,IF(F17<=$C$4,1,0))) | G30: =IF(G17="","",IF(G17<=0.8*$C$4,2,IF(G17<=$C$4,1,0))) | H30: =IF(H17="","",IF(H17<=0.8*$C$4,2,IF(H17<=$C$4,1,0))) | I30: =IF(I17="","",IF(I17<=0.8*$C$4,2,IF(I17<=$C$4,1,0))) | J30: =IF(J17="","",IF(J17<=0.8*$C$4,2,IF(J17<=$C$4,1,0))) | K30: =IF(K17="","",IF(K17<=0.8*$C$4,2,IF(K17<=$C$4,1,0)))
B32: Weighted score (0–100) | D32: =IF(COUNT(D21:D30)<10,"",ROUND(SUMPRODUCT($C$21:$C$30,D21:D30)/2*100,0)) -> 65 | E32: =IF(COUNT(E21:E30)<10,"",ROUND(SUMPRODUCT($C$21:$C$30,E21:E30)/2*100,0)) | F32: =IF(COUNT(F21:F30)<10,"",ROUND(SUMPRODUCT($C$21:$C$30,F21:F30)/2*100,0)) | G32: =IF(COUNT(G21:G30)<10,"",ROUND(SUMPRODUCT($C$21:$C$30,G21:G30)/2*100,0)) | H32: =IF(COUNT(H21:H30)<10,"",ROUND(SUMPRODUCT($C$21:$C$30,H21:H30)/2*100,0)) | I32: =IF(COUNT(I21:I30)<10,"",ROUND(SUMPRODUCT($C$21:$C$30,I21:I30)/2*100,0)) | J32: =IF(COUNT(J21:J30)<10,"",ROUND(SUMPRODUCT($C$21:$C$30,J21:J30)/2*100,0)) | K32: =IF(COUNT(K21:K30)<10,"",ROUND(SUMPRODUCT($C$21:$C$30,K21:K30)/2*100,0))
B33: Hard gates | D33: =IF(D18="NO","DISQUALIFIED: compliance",IF(D14="","—",IF(D14>=4,"DISQUALIFIED: single-season","OK"))) -> DISQUALIFIED: compliance | E33: =IF(E18="NO","DISQUALIFIED: compliance",IF(E14="","—",IF(E14>=4,"DISQUALIFIED: single-season","OK"))) -> — | F33: =IF(F18="NO","DISQUALIFIED: compliance",IF(F14="","—",IF(F14>=4,"DISQUALIFIED: single-season","OK"))) -> — | G33: =IF(G18="NO","DISQUALIFIED: compliance",IF(G14="","—",IF(G14>=4,"DISQUALIFIED: single-season","OK"))) -> — | H33: =IF(H18="NO","DISQUALIFIED: compliance",IF(H14="","—",IF(H14>=4,"DISQUALIFIED: single-season","OK"))) -> — | I33: =IF(I18="NO","DISQUALIFIED: compliance",IF(I14="","—",IF(I14>=4,"DISQUALIFIED: single-season","OK"))) -> — | J33: =IF(J18="NO","DISQUALIFIED: compliance",IF(J14="","—",IF(J14>=4,"DISQUALIFIED: single-season","OK"))) -> — | K33: =IF(K18="NO","DISQUALIFIED: compliance",IF(K14="","—",IF(K14>=4,"DISQUALIFIED: single-season","OK"))) -> —
B34: Verdict | D34: =IF(D32="","",IF(D33<>"OK","DROP",IF(D32>=70,"INVESTIGATE",IF(D32>=50,"PARK","DROP")))) -> DROP | E34: =IF(E32="","",IF(E33<>"OK","DROP",IF(E32>=70,"INVESTIGATE",IF(E32>=50,"PARK","DROP")))) | F34: =IF(F32="","",IF(F33<>"OK","DROP",IF(F32>=70,"INVESTIGATE",IF(F32>=50,"PARK","DROP")))) | G34: =IF(G32="","",IF(G33<>"OK","DROP",IF(G32>=70,"INVESTIGATE",IF(G32>=50,"PARK","DROP")))) | H34: =IF(H32="","",IF(H33<>"OK","DROP",IF(H32>=70,"INVESTIGATE",IF(H32>=50,"PARK","DROP")))) | I34: =IF(I32="","",IF(I33<>"OK","DROP",IF(I32>=70,"INVESTIGATE",IF(I32>=50,"PARK","DROP")))) | J34: =IF(J32="","",IF(J33<>"OK","DROP",IF(J32>=70,"INVESTIGATE",IF(J32>=50,"PARK","DROP")))) | K34: =IF(K32="","",IF(K33<>"OK","DROP",IF(K32>=70,"INVESTIGATE",IF(K32>=50,"PARK","DROP"))))
B36: ≥70 investigate · 50–69 park · <50 drop · any DISQUALIFIED = drop regardless of score.
B37: The score ranks research time. The final go/no-go is Sheets 1–4, never this score. Example column: a decent score killed by a hard gate — helmets are PPE Cat II.

Sheet 6 Order size
B1: =HYPERLINK("#Start!B2","← Start") -> ← Start
B2: First order size — newsvendor model
B3: Balances the margin you lose on a missed sale against the cost of a leftover unit. Give it a pessimistic and an optimistic season estimate; it returns the profit-maximizing quantity.
B5: Inputs
B6: Pessimistic season sales, units (P10) | C6: 600 | E6: Only ~10% chance sales come in below this. From Xray page-1 revenue × the share you think you can take.
B7: Optimistic season sales, units (P90) | C7: 1400 | E7: Only ~10% chance above this.
B8: Value recovered per leftover unit (EUR) | C8: 5 | E8: Clearance, Outlet, or removal — net of fees.
B9: Extra storage/removal per leftover unit (EUR) | C9: 1 | E9: Incl. aged-inventory surcharge risk.
B10: MOQ (units) | C10: 300 | E10: Supplier minimum.
B11: Budget for this PO (EUR) | C11: 5000 | E11: Cash available for goods (not ads).
B13: From other sheets
B14: Contribution margin per unit (Cu) | C14: ='3 Unit economics'!C29 -> 20.339571
B15: Landed cost per unit | C15: =-'3 Unit economics'!C27 -> 12.9294
B17: Calculation
B18: Expected season demand (mu) | C18: =(C6+C7)/2 -> 1000
B19: Demand uncertainty (sigma) | C19: =(C7-C6)/2.5631 -> 312.12204 | E19: Converts your P10–P90 range into a standard deviation.
B20: Cost of one leftover unit (Co) | C20: =C15+C9-C8 -> 8.9294 | E20: Landed + extra storage − recovery.
B21: Critical ratio Cu/(Cu+Co) | C21: =IFERROR(C14/(C14+C20),"") -> 0.69491923 | E21: The service level to buy. Above 50% = order MORE than average demand.
B22: Optimal quantity (unconstrained) | C22: =IFERROR(ROUND(NORMINV(C21,C18,C19),0),"") -> 1159
B23: Max affordable units (budget / landed) | C23: =IFERROR(INT(C11/C15),"") -> 386
B24: RECOMMENDED ORDER | C24: =IFERROR(MIN(MAX(C10,C22),C23),"") -> 386 | E24: Optimum clamped to MOQ and budget.
B25: z at recommended quantity | C25: =IFERROR((C24-C18)/C19,"") -> -1.9671793
B26: Expected lost sales (units) | C26: =IFERROR(ROUND(C19*(NORMDIST(C25,0,1,FALSE)-C25*(1-NORMSDIST(C25))),0),"") -> 617
B27: Expected leftover (units) | C27: =IFERROR(ROUND(C24-C18+C26,0),"") -> 3
B28: Expected season contribution (EUR) | C28: =IFERROR(ROUND(C14*(C18-C26)-C20*C27,0),"") -> 7763
B30: =IF(OR(C22="",C10=""),"",IF(C10>C22*1.2,"⚠ MOQ is far above the optimum — negotiate MOQ down or reconsider the product.",""))
B31: =IF(OR(C22="",C23=""),"",IF(C23<C22*0.8,"⚠ Budget caps you well below the optimum — plan the reorder date now (Sheet 8).","")) -> ⚠ Budget caps you well below the optimum — plan the reorder date now (Sheet 8).
B33: For a year-round product this sizes the seasonal chunk; you can reorder, so lean toward the lower end and reorder fast.
B35: P10/P90 helper — from Cerebro keyword sales (v4)
B36: Keyword sales per WEEK (Cerebro, niche keywords summed) | C36: 44 | E36: Cerebro column 'Keyword Sales' = purchases attributed to the keyword(s), counted PER WEEK (hover the column header in Cerebro - it says weekly). Rows 40/41 convert to months with x52/12. Earlier versions of this sheet read this figure as monthly, which made every suggested order about 4.3x too small. Sum the parent + main children, don't double-count overlapping terms.
B37: Months you are buying stock for | C37: 12
B38: Pessimistic share you capture | C38: 0.04
B39: Optimistic share you capture | C39: 0.15
B40: Suggested P10 (→ copy into C6) | C40: =IFERROR(ROUND(C36*(52/12)*C38*C37,0),"") -> 92
B41: Suggested P90 (→ copy into C7) | C41: =IFERROR(ROUND(C36*(52/12)*C39*C37,0),"") -> 343
B43: These are suggestions, not inputs the model reads automatically — sanity-check them against Xray page-1 unit sales before copying into C6/C7 above.

Sheet 7 PPC planner
B1: =HYPERLINK("#Start!B2","← Start") -> ← Start
B2: PPC planner — economics, launch budget, waste finder
B3: Top: what you can afford to pay for ads. Bottom: paste your Search Term Report and see the money leaking.
B5: Ad economics | I5: CPR launch push (v4)
B6: Gross price (incl. VAT) | C6: ='3 Unit economics'!C6 -> 59.99 | I6: CPR — units in 8 days (Cerebro) | J6: 39
B7: Contribution margin per unit | C7: ='3 Unit economics'!C29 -> 20.339571 | I7: Launch discount per unit (EUR) | J7: 3
B8: Breakeven ACOS | C8: =IFERROR(C7/C6,"") -> 0.33904935 | I8: Goods burned by the push | J8: =IFERROR(J6*('6 Order size'!C15+J7),"") -> 621.2466
B9: Breakeven ROAS | C9: =IFERROR(1/C8,"") -> 2.9494231 | I9: 8 days of launch ads | J9: =IFERROR(C18*8,"") -> 192
B10: Share of margin given to ads at steady state | C10: 0.3 | E10: 0.30 = you keep 70% of margin, ads take 30%. | I10: Total cost of the CPR push | J10: =IFERROR(J8+J9,"") -> 813.2466
B11: Target ACOS (profit phase) | C11: =IFERROR(C8*C10,"") -> 0.10171481
B12: Target ROAS | C12: =IFERROR(1/C11,"") -> 9.8314104 | I12: Compare against Sheet 3 margin × CPR units: if the push costs more than ~6 weeks of expected page-1 contribution, the keyword is too expensive to attack head-on — launch on a cheaper child keyword first.
B14: Launch budget
B15: Target ad-driven orders per day | C15: 3
B16: Estimated CPC (EUR) | C16: 0.8
B17: Estimated conversion rate | C17: 0.1 | E17: Clicks per order = 1 / CVR. 10% is a decent listing; below 7% fix the listing, not the bids.
B18: Daily ad spend | C18: =IFERROR(C15*C16/C17,"") -> 24
B19: Launch length (weeks) | C19: 4
B20: Launch ad budget | C20: =IFERROR(C18*7*C19,"") -> 672
B21: TACOS = ad spend ÷ TOTAL sales (ads + organic). Track it monthly in Sheet 9 — healthy: falling while sales grow.
B22: Waste finder — summary
B23: Flag 0-order terms with clicks ≥ | C23: 15
B24: …or spend ≥ (EUR) | C24: 10
B25: Wasted spend on 0-order terms | C25: =IFERROR(SUMIFS($D$30:$D$229,$E$30:$E$229,0,$B$30:$B$229,"<>"),0) -> 45
B26: Negative-keyword candidates | C26: =COUNTIF($G$30:$G$229,"ADD AS NEGATIVE") -> 2
B28: Paste your Search Term Report below (Ads console → Sponsored Products → Reports → Search term, 30–60 days). First 3 rows are examples — overwrite them.
B29: Search term | C29: Clicks | D29: Spend € | E29: Orders | F29: Sales € | G29: Flag
B30: fahrradhelm herren | C30: 42 | D30: 31.5 | E30: 3 | F30: 134.85 | G30: =IF(COUNT(C30:F30)<4,"",IF(AND(E30=0,OR(C30>=$C$23,D30>=$C$24)),"ADD AS NEGATIVE",IF(AND(F30>0,D30/F30>$C$8),"ACOS > BREAKEVEN","OK"))) -> OK
B31: helm kinder | C31: 23 | D31: 18.2 | E31: 0 | F31: 0 | G31: =IF(COUNT(C31:F31)<4,"",IF(AND(E31=0,OR(C31>=$C$23,D31>=$C$24)),"ADD AS NEGATIVE",IF(AND(F31>0,D31/F31>$C$8),"ACOS > BREAKEVEN","OK"))) -> ADD AS NEGATIVE
B32: motorradhelm | C32: 35 | D32: 26.8 | E32: 0 | F32: 0 | G32: =IF(COUNT(C32:F32)<4,"",IF(AND(E32=0,OR(C32>=$C$23,D32>=$C$24)),"ADD AS NEGATIVE",IF(AND(F32>0,D32/F32>$C$8),"ACOS > BREAKEVEN","OK"))) -> ADD AS NEGATIVE
G33: =IF(COUNT(C33:F33)<4,"",IF(AND(E33=0,OR(C33>=$C$23,D33>=$C$24)),"ADD AS NEGATIVE",IF(AND(F33>0,D33/F33>$C$8),"ACOS > BREAKEVEN","OK")))
G34: =IF(COUNT(C34:F34)<4,"",IF(AND(E34=0,OR(C34>=$C$23,D34>=$C$24)),"ADD AS NEGATIVE",IF(AND(F34>0,D34/F34>$C$8),"ACOS > BREAKEVEN","OK")))
G35: =IF(COUNT(C35:F35)<4,"",IF(AND(E35=0,OR(C35>=$C$23,D35>=$C$24)),"ADD AS NEGATIVE",IF(AND(F35>0,D35/F35>$C$8),"ACOS > BREAKEVEN","OK")))
G36: =IF(COUNT(C36:F36)<4,"",IF(AND(E36=0,OR(C36>=$C$23,D36>=$C$24)),"ADD AS NEGATIVE",IF(AND(F36>0,D36/F36>$C$8),"ACOS > BREAKEVEN","OK")))
G37: =IF(COUNT(C37:F37)<4,"",IF(AND(E37=0,OR(C37>=$C$23,D37>=$C$24)),"ADD AS NEGATIVE",IF(AND(F37>0,D37/F37>$C$8),"ACOS > BREAKEVEN","OK")))
G38: =IF(COUNT(C38:F38)<4,"",IF(AND(E38=0,OR(C38>=$C$23,D38>=$C$24)),"ADD AS NEGATIVE",IF(AND(F38>0,D38/F38>$C$8),"ACOS > BREAKEVEN","OK")))
G39: =IF(COUNT(C39:F39)<4,"",IF(AND(E39=0,OR(C39>=$C$23,D39>=$C$24)),"ADD AS NEGATIVE",IF(AND(F39>0,D39/F39>$C$8),"ACOS > BREAKEVEN","OK")))
G40: =IF(COUNT(C40:F40)<4,"",IF(AND(E40=0,OR(C40>=$C$23,D40>=$C$24)),"ADD AS NEGATIVE",IF(AND(F40>0,D40/F40>$C$8),"ACOS > BREAKEVEN","OK")))
G41: =IF(COUNT(C41:F41)<4,"",IF(AND(E41=0,OR(C41>=$C$23,D41>=$C$24)),"ADD AS NEGATIVE",IF(AND(F41>0,D41/F41>$C$8),"ACOS > BREAKEVEN","OK")))
G42: =IF(COUNT(C42:F42)<4,"",IF(AND(E42=0,OR(C42>=$C$23,D42>=$C$24)),"ADD AS NEGATIVE",IF(AND(F42>0,D42/F42>$C$8),"ACOS > BREAKEVEN","OK")))
G43: =IF(COUNT(C43:F43)<4,"",IF(AND(E43=0,OR(C43>=$C$23,D43>=$C$24)),"ADD AS NEGATIVE",IF(AND(F43>0,D43/F43>$C$8),"ACOS > BREAKEVEN","OK")))
...

Sheet 8 Cash flow
B1: =HYPERLINK("#Start!B2","← Start") -> ← Start
B2: First-order cash plan — 12 months
B3: Money leaves in lumps and comes back as a drip. If the cumulative line goes below zero, the plan is not funded.
B5: Inputs
B6: Order quantity | C6: ='6 Order size'!C24 -> 386
B7: Landed cost per unit | C7: ='6 Order size'!C15 -> 12.9294
B8: PO value (goods, landed) | C8: =IFERROR(C6*C7,"") -> 4990.7484
B9: Deposit share at order (month 0) | C9: 0.3
B10: Balance paid in month # | C10: 2
B11: Goods arrive in month # | C11: 3
B12: Import VAT paid at arrival (≈19% of PO) | C12: =IFERROR(ROUND(0.19*C8,0),"") -> 948
B13: Import VAT refunded after (months) | C13: 2
B14: Amazon payout per unit sold | C14: ='3 Unit economics'!C26 -> 33.773088
B15: Starting cash available (EUR) | C15: 6500
B16: Month | C16: Units sold | D16: Ads+fixed € | E16: Cash out € | F16: Cash in € | G16: Net € | H16: Cumulative €
B17: 0 | C17: 0 | D17: 0 | E17: =ROUND(IF($B17=0,$C$9*$C$8,0)+IF($B17=$C$10,(1-$C$9)*$C$8,0)+IF($B17=$C$11,$C$12,0)+D17,0) -> 1497 | F17: =ROUND(C17*$C$14+IF($B17=$C$11+$C$13,$C$12,0),0) -> 0 | G17: =F17-E17 -> -1497 | H17: =$C$15+G17 -> 5003 | I17: Units plan: copy the seasonal shape from Sheet 1; example follows a spring ramp.
B18: 1 | C18: 0 | D18: 0 | E18: =ROUND(IF($B18=0,$C$9*$C$8,0)+IF($B18=$C$10,(1-$C$9)*$C$8,0)+IF($B18=$C$11,$C$12,0)+D18,0) -> 0 | F18: =ROUND(C18*$C$14+IF($B18=$C$11+$C$13,$C$12,0),0) -> 0 | G18: =F18-E18 -> 0 | H18: =H17+G18 -> 5003
B19: 2 | C19: 0 | D19: 0 | E19: =ROUND(IF($B19=0,$C$9*$C$8,0)+IF($B19=$C$10,(1-$C$9)*$C$8,0)+IF($B19=$C$11,$C$12,0)+D19,0) -> 3494 | F19: =ROUND(C19*$C$14+IF($B19=$C$11+$C$13,$C$12,0),0) -> 0 | G19: =F19-E19 -> -3494 | H19: =H18+G19 -> 1509
B20: 3 | C20: 60 | D20: 700 | E20: =ROUND(IF($B20=0,$C$9*$C$8,0)+IF($B20=$C$10,(1-$C$9)*$C$8,0)+IF($B20=$C$11,$C$12,0)+D20,0) -> 1648 | F20: =ROUND(C20*$C$14+IF($B20=$C$11+$C$13,$C$12,0),0) -> 2026 | G20: =F20-E20 -> 378 | H20: =H19+G20 -> 1887 | I20: Ads column: launch-heavy, from Sheet 7's launch budget, then steady state.
B21: 4 | C21: 90 | D21: 700 | E21: =ROUND(IF($B21=0,$C$9*$C$8,0)+IF($B21=$C$10,(1-$C$9)*$C$8,0)+IF($B21=$C$11,$C$12,0)+D21,0) -> 700 | F21: =ROUND(C21*$C$14+IF($B21=$C$11+$C$13,$C$12,0),0) -> 3040 | G21: =F21-E21 -> 2340 | H21: =H20+G21 -> 4227
B22: 5 | C22: 110 | D22: 500 | E22: =ROUND(IF($B22=0,$C$9*$C$8,0)+IF($B22=$C$10,(1-$C$9)*$C$8,0)+IF($B22=$C$11,$C$12,0)+D22,0) -> 500 | F22: =ROUND(C22*$C$14+IF($B22=$C$11+$C$13,$C$12,0),0) -> 4663 | G22: =F22-E22 -> 4163 | H22: =H21+G22 -> 8390
B23: 6 | C23: 120 | D23: 400 | E23: =ROUND(IF($B23=0,$C$9*$C$8,0)+IF($B23=$C$10,(1-$C$9)*$C$8,0)+IF($B23=$C$11,$C$12,0)+D23,0) -> 400 | F23: =ROUND(C23*$C$14+IF($B23=$C$11+$C$13,$C$12,0),0) -> 4053 | G23: =F23-E23 -> 3653 | H23: =H22+G23 -> 12043
B24: 7 | C24: 120 | D24: 400 | E24: =ROUND(IF($B24=0,$C$9*$C$8,0)+IF($B24=$C$10,(1-$C$9)*$C$8,0)+IF($B24=$C$11,$C$12,0)+D24,0) -> 400 | F24: =ROUND(C24*$C$14+IF($B24=$C$11+$C$13,$C$12,0),0) -> 4053 | G24: =F24-E24 -> 3653 | H24: =H23+G24 -> 15696
B25: 8 | C25: 100 | D25: 350 | E25: =ROUND(IF($B25=0,$C$9*$C$8,0)+IF($B25=$C$10,(1-$C$9)*$C$8,0)+IF($B25=$C$11,$C$12,0)+D25,0) -> 350 | F25: =ROUND(C25*$C$14+IF($B25=$C$11+$C$13,$C$12,0),0) -> 3377 | G25: =F25-E25 -> 3027 | H25: =H24+G25 -> 18723
B26: 9 | C26: 80 | D26: 300 | E26: =ROUND(IF($B26=0,$C$9*$C$8,0)+IF($B26=$C$10,(1-$C$9)*$C$8,0)+IF($B26=$C$11,$C$12,0)+D26,0) -> 300 | F26: =ROUND(C26*$C$14+IF($B26=$C$11+$C$13,$C$12,0),0) -> 2702 | G26: =F26-E26 -> 2402 | H26: =H25+G26 -> 21125
B27: 10 | C27: 60 | D27: 250 | E27: =ROUND(IF($B27=0,$C$9*$C$8,0)+IF($B27=$C$10,(1-$C$9)*$C$8,0)+IF($B27=$C$11,$C$12,0)+D27,0) -> 250 | F27: =ROUND(C27*$C$14+IF($B27=$C$11+$C$13,$C$12,0),0) -> 2026 | G27: =F27-E27 -> 1776 | H27: =H26+G27 -> 22901
B28: 11 | C28: 40 | D28: 200 | E28: =ROUND(IF($B28=0,$C$9*$C$8,0)+IF($B28=$C$10,(1-$C$9)*$C$8,0)+IF($B28=$C$11,$C$12,0)+D28,0) -> 200 | F28: =ROUND(C28*$C$14+IF($B28=$C$11+$C$13,$C$12,0),0) -> 1351 | G28: =F28-E28 -> 1151 | H28: =H27+G28 -> 24052
B29: 12 | C29: 20 | D29: 150 | E29: =ROUND(IF($B29=0,$C$9*$C$8,0)+IF($B29=$C$10,(1-$C$9)*$C$8,0)+IF($B29=$C$11,$C$12,0)+D29,0) -> 150 | F29: =ROUND(C29*$C$14+IF($B29=$C$11+$C$13,$C$12,0),0) -> 675 | G29: =F29-E29 -> 525 | H29: =H28+G29 -> 24577
B32: Lowest cash point | C32: =MIN(H17:H29) -> 1509
B33: =IF(C32<0,"⚠ Cash goes below zero — cut the order (Sheet 6), stretch supplier terms, or add capital before ordering.","OK — the plan stays funded.") -> OK — the plan stays funded.
B35: Not included: your salary, Georgian 1% tax timing, the reorder. Add the reorder as extra cash-out rows when you plan it — running out of stock in season kills launches (Sheet 4, block C).
B37: Cash cycle (days per euro, v4) | C37: ='2 Order timing'!C18+45+14 -> 190
B38: Cash turns per year | C38: =IFERROR(ROUND(365/C37,1),"") -> 1.9

Sheet 9 Monthly P&L
B1: =HYPERLINK("#Start!B2","← Start") -> ← Start
B2: Monthly P&L — the real profit, per month
B3: Fill monthly from Payments → Reports repository → Date Range Report (Summary) and the Ads console. Enter costs as POSITIVE numbers. Row 6 is an example — overwrite it.
B5: Month | C5: Units | D5: Gross sales € | E5: Amazon fees € | F5: Refunds € | G5: PPC € | H5: Storage+other € | I5: COGS € (auto) | J5: Tax € (auto) | K5: Net profit € | L5: Margin % | M5: TACOS
B6: Jan | C6: 90 | D6: 5399 | E6: 1260 | F6: 180 | G6: 620 | H6: 90 | I6: =IF(C6="","",ROUND(C6*'6 Order size'!$C$15,0)) -> 1164 | J6: =IF(D6="","",ROUND('3 Unit economics'!$C$18*D6/(1+'3 Unit economics'!$C$7),0)) -> 45 | K6: =IF(D6="","",ROUND(D6/(1+'3 Unit economics'!$C$7)-E6-F6-G6-H6-I6-J6,0)) -> 1178 | L6: =IF(D6="","",K6/(D6/(1+'3 Unit economics'!$C$7))) -> 0.25964438 | M6: =IF(OR(D6="",G6=""),"",G6/D6) -> 0.11483608
B7: Feb | I7: =IF(C7="","",ROUND(C7*'6 Order size'!$C$15,0)) | J7: =IF(D7="","",ROUND('3 Unit economics'!$C$18*D7/(1+'3 Unit economics'!$C$7),0)) | K7: =IF(D7="","",ROUND(D7/(1+'3 Unit economics'!$C$7)-E7-F7-G7-H7-I7-J7,0)) | L7: =IF(D7="","",K7/(D7/(1+'3 Unit economics'!$C$7))) | M7: =IF(OR(D7="",G7=""),"",G7/D7)
B8: Mar | I8: =IF(C8="","",ROUND(C8*'6 Order size'!$C$15,0)) | J8: =IF(D8="","",ROUND('3 Unit economics'!$C$18*D8/(1+'3 Unit economics'!$C$7),0)) | K8: =IF(D8="","",ROUND(D8/(1+'3 Unit economics'!$C$7)-E8-F8-G8-H8-I8-J8,0)) | L8: =IF(D8="","",K8/(D8/(1+'3 Unit economics'!$C$7))) | M8: =IF(OR(D8="",G8=""),"",G8/D8)
B9: Apr | I9: =IF(C9="","",ROUND(C9*'6 Order size'!$C$15,0)) | J9: =IF(D9="","",ROUND('3 Unit economics'!$C$18*D9/(1+'3 Unit economics'!$C$7),0)) | K9: =IF(D9="","",ROUND(D9/(1+'3 Unit economics'!$C$7)-E9-F9-G9-H9-I9-J9,0)) | L9: =IF(D9="","",K9/(D9/(1+'3 Unit economics'!$C$7))) | M9: =IF(OR(D9="",G9=""),"",G9/D9)
B10: May | I10: =IF(C10="","",ROUND(C10*'6 Order size'!$C$15,0)) | J10: =IF(D10="","",ROUND('3 Unit economics'!$C$18*D10/(1+'3 Unit economics'!$C$7),0)) | K10: =IF(D10="","",ROUND(D10/(1+'3 Unit economics'!$C$7)-E10-F10-G10-H10-I10-J10,0)) | L10: =IF(D10="","",K10/(D10/(1+'3 Unit economics'!$C$7))) | M10: =IF(OR(D10="",G10=""),"",G10/D10)
B11: Jun | I11: =IF(C11="","",ROUND(C11*'6 Order size'!$C$15,0)) | J11: =IF(D11="","",ROUND('3 Unit economics'!$C$18*D11/(1+'3 Unit economics'!$C$7),0)) | K11: =IF(D11="","",ROUND(D11/(1+'3 Unit economics'!$C$7)-E11-F11-G11-H11-I11-J11,0)) | L11: =IF(D11="","",K11/(D11/(1+'3 Unit economics'!$C$7))) | M11: =IF(OR(D11="",G11=""),"",G11/D11)
B12: Jul | I12: =IF(C12="","",ROUND(C12*'6 Order size'!$C$15,0)) | J12: =IF(D12="","",ROUND('3 Unit economics'!$C$18*D12/(1+'3 Unit economics'!$C$7),0)) | K12: =IF(D12="","",ROUND(D12/(1+'3 Unit economics'!$C$7)-E12-F12-G12-H12-I12-J12,0)) | L12: =IF(D12="","",K12/(D12/(1+'3 Unit economics'!$C$7))) | M12: =IF(OR(D12="",G12=""),"",G12/D12)
B13: Aug | I13: =IF(C13="","",ROUND(C13*'6 Order size'!$C$15,0)) | J13: =IF(D13="","",ROUND('3 Unit economics'!$C$18*D13/(1+'3 Unit economics'!$C$7),0)) | K13: =IF(D13="","",ROUND(D13/(1+'3 Unit economics'!$C$7)-E13-F13-G13-H13-I13-J13,0)) | L13: =IF(D13="","",K13/(D13/(1+'3 Unit economics'!$C$7))) | M13: =IF(OR(D13="",G13=""),"",G13/D13)
B14: Sep | I14: =IF(C14="","",ROUND(C14*'6 Order size'!$C$15,0)) | J14: =IF(D14="","",ROUND('3 Unit economics'!$C$18*D14/(1+'3 Unit economics'!$C$7),0)) | K14: =IF(D14="","",ROUND(D14/(1+'3 Unit economics'!$C$7)-E14-F14-G14-H14-I14-J14,0)) | L14: =IF(D14="","",K14/(D14/(1+'3 Unit economics'!$C$7))) | M14: =IF(OR(D14="",G14=""),"",G14/D14)
B15: Oct | I15: =IF(C15="","",ROUND(C15*'6 Order size'!$C$15,0)) | J15: =IF(D15="","",ROUND('3 Unit economics'!$C$18*D15/(1+'3 Unit economics'!$C$7),0)) | K15: =IF(D15="","",ROUND(D15/(1+'3 Unit economics'!$C$7)-E15-F15-G15-H15-I15-J15,0)) | L15: =IF(D15="","",K15/(D15/(1+'3 Unit economics'!$C$7))) | M15: =IF(OR(D15="",G15=""),"",G15/D15)
B16: Nov | I16: =IF(C16="","",ROUND(C16*'6 Order size'!$C$15,0)) | J16: =IF(D16="","",ROUND('3 Unit economics'!$C$18*D16/(1+'3 Unit economics'!$C$7),0)) | K16: =IF(D16="","",ROUND(D16/(1+'3 Unit economics'!$C$7)-E16-F16-G16-H16-I16-J16,0)) | L16: =IF(D16="","",K16/(D16/(1+'3 Unit economics'!$C$7))) | M16: =IF(OR(D16="",G16=""),"",G16/D16)
B17: Dec | I17: =IF(C17="","",ROUND(C17*'6 Order size'!$C$15,0)) | J17: =IF(D17="","",ROUND('3 Unit economics'!$C$18*D17/(1+'3 Unit economics'!$C$7),0)) | K17: =IF(D17="","",ROUND(D17/(1+'3 Unit economics'!$C$7)-E17-F17-G17-H17-I17-J17,0)) | L17: =IF(D17="","",K17/(D17/(1+'3 Unit economics'!$C$7))) | M17: =IF(OR(D17="",G17=""),"",G17/D17)
B18: Total | C18: =SUM(C6:C17) -> 90 | D18: =SUM(D6:D17) -> 5399 | E18: =SUM(E6:E17) -> 1260 | F18: =SUM(F6:F17) -> 180 | G18: =SUM(G6:G17) -> 620 | H18: =SUM(H6:H17) -> 90 | I18: =SUM(I6:I17) -> 1164 | J18: =SUM(J6:J17) -> 45 | K18: =SUM(K6:K17) -> 1178 | L18: =IF(D18=0,"",K18/(D18/(1+'3 Unit economics'!$C$7))) -> 0.25964438 | M18: =IF(D18=0,"",G18/D18) -> 0.11483608
B20: Net profit = gross/1.19 − fees − refunds − PPC − storage − COGS − 1% turnover tax. VAT never reaches you (deemed supplier), so it is excluded on both sides.
B21: Cross-check: Margin % here should converge to Sheet 3's margin as volumes stabilize. If it is far lower, hunt the difference: storage, refunds, PPC.

Sheet 10 Money recovery
B1: =HYPERLINK("#Start!B2","← Start") -> ← Start
B2: Money recovery — what Amazon owes you
B3: Sellers lose 1–3% of revenue to unclaimed reimbursements. The claim window is 60 DAYS, and since Mar 2025 auto-reimbursements cover only your manufacturing cost — check monthly, claim actively.
B5: Adjustments without a matching reimbursement: | C5: =COUNTIF($F$12:$F$61,"NOT REIMBURSED — check & claim") -> 1
B7: A — paste Inventory Adjustments (Reports → Fulfilment by Amazon → Inventory Adjustments; filter Lost, Damaged, Disposed). Rows 12–13 are examples.
B11: Date | C11: FNSKU | D11: Reason | E11: Qty | F11: Status
B12: 46206 | C12: X001ABC | D12: Lost | E12: 2 | F12: =IF($C12="","",IF(COUNTIF($C$68:$C$117,$C12)>0,"Reimbursement found — verify amount","NOT REIMBURSED — check & claim")) -> Reimbursement found — verify amount
B13: 46222 | C13: X002DEF | D13: Damaged | E13: 1 | F13: =IF($C13="","",IF(COUNTIF($C$68:$C$117,$C13)>0,"Reimbursement found — verify amount","NOT REIMBURSED — check & claim")) -> NOT REIMBURSED — check & claim
F14: =IF($C14="","",IF(COUNTIF($C$68:$C$117,$C14)>0,"Reimbursement found — verify amount","NOT REIMBURSED — check & claim"))
F15: =IF($C15="","",IF(COUNTIF($C$68:$C$117,$C15)>0,"Reimbursement found — verify amount","NOT REIMBURSED — check & claim"))
F16: =IF($C16="","",IF(COUNTIF($C$68:$C$117,$C16)>0,"Reimbursement found — verify amount","NOT REIMBURSED — check & claim"))
F17: =IF($C17="","",IF(COUNTIF($C$68:$C$117,$C17)>0,"Reimbursement found — verify amount","NOT REIMBURSED — check & claim"))
F18: =IF($C18="","",IF(COUNTIF($C$68:$C$117,$C18)>0,"Reimbursement found — verify amount","NOT REIMBURSED — check & claim"))
F19: =IF($C19="","",IF(COUNTIF($C$68:$C$117,$C19)>0,"Reimbursement found — verify amount","NOT REIMBURSED — check & claim"))
F20: =IF($C20="","",IF(COUNTIF($C$68:$C$117,$C20)>0,"Reimbursement found — verify amount","NOT REIMBURSED — check & claim"))
F21: =IF($C21="","",IF(COUNTIF($C$68:$C$117,$C21)>0,"Reimbursement found — verify amount","NOT REIMBURSED — check & claim"))
F22: =IF($C22="","",IF(COUNTIF($C$68:$C$117,$C22)>0,"Reimbursement found — verify amount","NOT REIMBURSED — check & claim"))
F23: =IF($C23="","",IF(COUNTIF($C$68:$C$117,$C23)>0,"Reimbursement found — verify amount","NOT REIMBURSED — check & claim"))
F24: =IF($C24="","",IF(COUNTIF($C$68:$C$117,$C24)>0,"Reimbursement found — verify amount","NOT REIMBURSED — check & claim"))
F25: =IF($C25="","",IF(COUNTIF($C$68:$C$117,$C25)>0,"Reimbursement found — verify amount","NOT REIMBURSED — check & claim"))
... F61: =IF($C61="","",IF(COUNTIF($C$68:$C$117,$C61)>0,"Reimbursement found — verify amount","NOT REIMBURSED — check & claim"))
B64: B — paste Reimbursements (Reports → Fulfilment by Amazon → Payments → Reimbursements). Row 68 is an example.
B67: Date | C67: FNSKU | D67: Amount €
B68: 46224 | C68: X001ABC | D68: 18.4
B120: C — FBA fee sanity check (fee overcharges from wrong measurements)
B121: Length (cm) | C121: 25
B122: Width (cm) | C122: 18
B123: Height (cm) | C123: 4
B124: Unit weight (g) | C124: 350
B125: FBA fee you are charged (EUR) | C125: 4.55
B126: Volume (litres) | C126: =ROUND(C121*C122*C123/1000,2) -> 1.8
B127: Longest side (cm) | C127: =MAX(C121:C123) -> 25
B129: Compare volume, longest side and weight against the current size tiers in Seller Central → 'FBA fulfilment fees rate card'. If your true tier is smaller than the fee implies, request a re-measure (case: FBA → Fee dispute). Amazon's measurements drift — recheck after every restock.
B131: Monthly audit routine | C131: Done?
B132: Adjustments report pulled and pasted (last 60 days) | C132: NO
B133: Reimbursements report pulled and pasted | C133: NO
B134: All flags above opened as cases | C134: NO
B135: Returns: refunds older than 60 days without item back → claim | C135: NO
B136: FBA fee vs dimensions rechecked after last restock | C136: NO

Sheet 11 Review themes
B1: =HYPERLINK("#Start!B2","← Start") -> ← Start
B2: Review themes — find the complaint to attack
B3: Export 1–3★ reviews of the top 5–10 ASINs (H10 Review Insights, last 12 months). Ask an AI assistant: 'cluster these reviews into complaint themes with counts'. Enter the themes below. Example data shown — overwrite.
B5: Niche / ASIN set | C5: satteltasche fahrrad
B7: Complaint theme | C7: Count | D7: Share
B8: Wobbles / mount comes loose | C8: 46 | D8: =IF(C8="","",C8/SUM($C$8:$C$17)) -> 0.42592593
B9: Straps tear | C9: 21 | D9: =IF(C9="","",C9/SUM($C$8:$C$17)) -> 0.19444444
B10: Not actually waterproof | C10: 18 | D10: =IF(C10="","",C10/SUM($C$8:$C$17)) -> 0.16666667
B11: Too small / fit unclear | C11: 15 | D11: =IF(C11="","",C11/SUM($C$8:$C$17)) -> 0.13888889
B12: Zipper fails | C12: 8 | D12: =IF(C12="","",C12/SUM($C$8:$C$17)) -> 0.074074074
D13: =IF(C13="","",C13/SUM($C$8:$C$17))
D14: =IF(C14="","",C14/SUM($C$8:$C$17))
D15: =IF(C15="","",C15/SUM($C$8:$C$17))
D16: =IF(C16="","",C16/SUM($C$8:$C$17))
D17: =IF(C17="","",C17/SUM($C$8:$C$17))
B19: Dominant theme | C19: =IFERROR(INDEX(B8:B17,MATCH(MAX(C8:C17),C8:C17,0)),"—") -> Wobbles / mount comes loose
B20: Its share of all complaints | C20: =IFERROR(MAX(C8:C17)/SUM(C8:C17),"") -> 0.42592593
B21: Verdict | C21: =IF(C20="","",IF(C20>=0.4,"≥40% — you have an attack hypothesis (Sheet 4, block B).","No dominant theme — weak differentiation basis.")) -> ≥40% — you have an attack hypothesis (Sheet 4, block B).
B23: Fake-review check — YES = red flag present
B24: Review bursts: many reviews landing within a few days | C24: NO
B25: Rating drifting down over 6 months after an early 4.7+ | C25: NO
B26: Generic / repeated phrasing, or wrong product described | C26: NO
B27: High share of unverified purchases | C27: NO
B28: Oldest reviews describe a DIFFERENT product (listing merge) | C28: NO
B29: Reviewer profiles: many unrelated 5★ reviews same day | C29: NO
B30: Red flags | C30: =COUNTIF(C24:C29,"YES") -> 0
B31: Verdict | C31: =IF(C30>=2,"Treat this review wall as partly fake — the moat is weaker than it looks (adjust Sheet 5, review moat).","No strong fake signals.") -> No strong fake signals.
B33: Keepa's review-count history chart shows bursts in ten seconds per ASIN. Method: He, Hollenbeck & Proserpio, Marketing Science 2022.

Sheet 12 Multi-year plan
B1: =HYPERLINK("#Start!B2","← Start") -> ← Start
B2: Multi-year plan — 12 quarters, up to 3 staggered launches
B3: The business-level question Sheet 8 cannot answer: if product 2 launches while product 1 is still ramping, does the combined plan ever run out of cash? Quarterly and deliberately coarse — Sheet 8 stays the fine-grained monthly check per product.
B5: Global inputs
B6: Starting cash (from Sheet 8) | C6: ='8 Cash flow'!C15 -> 6500
B7: Fixed costs per quarter (EUR) | C7: 400 | E7: Helium 10, LUCID/EPR fees, accountant, software — everything that bills regardless of sales.
B8: Launch-quarter sales share (ramp) | C8: 0.4
B10: Products (leave a column empty to plan fewer) | C10: Product 1 | D10: Product 2 | E10: Product 3
B11: Launch quarter (1–12) | C11: 1 | D11: 3
B12: Mature sales, units per QUARTER | C12: 300 | D12: 300
B13: Payout per unit after tax (EUR) | C13: ='3 Unit economics'!C26+'3 Unit economics'!C28 -> 33.268971 | D13: 20 | F13: Product 1 pulls from Sheet 3 (Amazon payout minus 1% turnover tax). For products 2–3, run Sheet 3 per product and type the result.
B14: Landed cost per unit (EUR) | C14: ='6 Order size'!C15 -> 12.9294 | D14: 13
B15: One-off launch cash (first PO + compliance + launch extras) | C15: 6000 | D15: 6500
B16: Ongoing ads per unit sold (EUR) | C16: 3 | D16: 3 | F16: Steady-state ad cost per unit ≈ target ACOS × gross price (Sheet 7).
C18: Year 1 | G18: Year 2 | K18: Year 3
B19: Quarter | C19: 1 | D19: 2 | E19: 3 | F19: 4 | G19: 5 | H19: 6 | I19: 7 | J19: 8 | K19: 9 | L19: 10 | M19: 11 | N19: 12
B20: Units sold — product 1 | C20: =IF(OR($C$11="",C$19<$C$11),0,ROUND($C$12*IF(C$19-$C$11=0,$C$8,IF(C$19-$C$11=1,($C$8+1)/2,1)),0)) -> 120 | D20: =IF(OR($C$11="",D$19<$C$11),0,ROUND($C$12*IF(D$19-$C$11=0,$C$8,IF(D$19-$C$11=1,($C$8+1)/2,1)),0)) -> 210 | E20: =IF(OR($C$11="",E$19<$C$11),0,ROUND($C$12*IF(E$19-$C$11=0,$C$8,IF(E$19-$C$11=1,($C$8+1)/2,1)),0)) -> 300 | F20: =IF(OR($C$11="",F$19<$C$11),0,ROUND($C$12*IF(F$19-$C$11=0,$C$8,IF(F$19-$C$11=1,($C$8+1)/2,1)),0)) -> 300 | G20: =IF(OR($C$11="",G$19<$C$11),0,ROUND($C$12*IF(G$19-$C$11=0,$C$8,IF(G$19-$C$11=1,($C$8+1)/2,1)),0)) -> 300 | H20: =IF(OR($C$11="",H$19<$C$11),0,ROUND($C$12*IF(H$19-$C$11=0,$C$8,IF(H$19-$C$11=1,($C$8+1)/2,1)),0)) -> 300 | I20: =IF(OR($C$11="",I$19<$C$11),0,ROUND($C$12*IF(I$19-$C$11=0,$C$8,IF(I$19-$C$11=1,($C$8+1)/2,1)),0)) -> 300 | J20: =IF(OR($C$11="",J$19<$C$11),0,ROUND($C$12*IF(J$19-$C$11=0,$C$8,IF(J$19-$C$11=1,($C$8+1)/2,1)),0)) -> 300 | ... N20: =IF(OR($C$11="",N$19<$C$11),0,ROUND($C$12*IF(N$19-$C$11=0,$C$8,IF(N$19-$C$11=1,($C$8+1)/2,1)),0)) -> 300
B21: Units sold — product 2 | C21: =IF(OR($D$11="",C$19<$D$11),0,ROUND($D$12*IF(C$19-$D$11=0,$C$8,IF(C$19-$D$11=1,($C$8+1)/2,1)),0)) -> 0 | D21: =IF(OR($D$11="",D$19<$D$11),0,ROUND($D$12*IF(D$19-$D$11=0,$C$8,IF(D$19-$D$11=1,($C$8+1)/2,1)),0)) -> 0 | E21: =IF(OR($D$11="",E$19<$D$11),0,ROUND($D$12*IF(E$19-$D$11=0,$C$8,IF(E$19-$D$11=1,($C$8+1)/2,1)),0)) -> 120 | F21: =IF(OR($D$11="",F$19<$D$11),0,ROUND($D$12*IF(F$19-$D$11=0,$C$8,IF(F$19-$D$11=1,($C$8+1)/2,1)),0)) -> 210 | G21: =IF(OR($D$11="",G$19<$D$11),0,ROUND($D$12*IF(G$19-$D$11=0,$C$8,IF(G$19-$D$11=1,($C$8+1)/2,1)),0)) -> 300 | H21: =IF(OR($D$11="",H$19<$D$11),0,ROUND($D$12*IF(H$19-$D$11=0,$C$8,IF(H$19-$D$11=1,($C$8+1)/2,1)),0)) -> 300 | I21: =IF(OR($D$11="",I$19<$D$11),0,ROUND($D$12*IF(I$19-$D$11=0,$C$8,IF(I$19-$D$11=1,($C$8+1)/2,1)),0)) -> 300 | J21: =IF(OR($D$11="",J$19<$D$11),0,ROUND($D$12*IF(J$19-$D$11=0,$C$8,IF(J$19-$D$11=1,($C$8+1)/2,1)),0)) -> 300 | ... N21: =IF(OR($D$11="",N$19<$D$11),0,ROUND($D$12*IF(N$19-$D$11=0,$C$8,IF(N$19-$D$11=1,($C$8+1)/2,1)),0)) -> 300
